fill ~ ~-2 ~ ~29 ~30 ~29 air

fill ~4 ~0 ~4 ~25 ~0 ~25 polished_deepslate
fill ~4 ~1 ~4 ~25 ~6 ~25 red_nether_bricks
fill ~5 ~1 ~5 ~24 ~6 ~24 air

fill ~4 ~1 ~4 ~25 ~6 ~4 red_nether_bricks
fill ~4 ~1 ~25 ~25 ~6 ~25 red_nether_bricks
fill ~4 ~1 ~4 ~4 ~6 ~25 red_nether_bricks
fill ~25 ~1 ~4 ~25 ~6 ~25 red_nether_bricks

fill ~13 ~1 ~4 ~16 ~3 ~4 air
setblock ~14 ~1 ~4 oak_door[facing=south,half=lower]
setblock ~14 ~2 ~4 oak_door[facing=south,half=upper]
setblock ~15 ~1 ~4 oak_door[facing=south,half=lower]
setblock ~15 ~2 ~4 oak_door[facing=south,half=upper]

fill ~6 ~2 ~4 ~10 ~4 ~4 air
fill ~19 ~2 ~4 ~23 ~4 ~4 air
fill ~6 ~2 ~4 ~10 ~4 ~4 white_stained_glass_pane
fill ~19 ~2 ~4 ~23 ~4 ~4 white_stained_glass_pane

fill ~4 ~2 ~7 ~4 ~4 ~11 air
fill ~4 ~2 ~18 ~4 ~4 ~22 air
fill ~25 ~2 ~7 ~25 ~4 ~11 air
fill ~25 ~2 ~18 ~25 ~4 ~22 air
fill ~4 ~2 ~7 ~4 ~4 ~11 white_stained_glass_pane
fill ~4 ~2 ~18 ~4 ~4 ~22 white_stained_glass_pane
fill ~25 ~2 ~7 ~25 ~4 ~11 white_stained_glass_pane
fill ~25 ~2 ~18 ~25 ~4 ~22 white_stained_glass_pane

fill ~7 ~2 ~25 ~11 ~4 ~25 air
fill ~18 ~2 ~25 ~22 ~4 ~25 air
fill ~7 ~2 ~25 ~11 ~4 ~25 white_stained_glass_pane
fill ~18 ~2 ~25 ~22 ~4 ~25 white_stained_glass_pane

fill ~5 ~1 ~3 ~5 ~6 ~3 quartz_pillar[axis=y]
fill ~7 ~1 ~3 ~7 ~6 ~3 quartz_pillar[axis=y]
fill ~9 ~1 ~3 ~9 ~6 ~3 quartz_pillar[axis=y]
fill ~11 ~1 ~3 ~11 ~6 ~3 quartz_pillar[axis=y]
fill ~18 ~1 ~3 ~18 ~6 ~3 quartz_pillar[axis=y]
fill ~20 ~1 ~3 ~20 ~6 ~3 quartz_pillar[axis=y]
fill ~22 ~1 ~3 ~22 ~6 ~3 quartz_pillar[axis=y]
fill ~24 ~1 ~3 ~24 ~6 ~3 quartz_pillar[axis=y]

fill ~4 ~1 ~3 ~25 ~1 ~3 polished_deepslate
fill ~12 ~1 ~3 ~17 ~1 ~3 red_carpet

setblock ~6 ~5 ~3 lantern[hanging=true]
setblock ~10 ~5 ~3 lantern[hanging=true]
setblock ~20 ~5 ~3 lantern[hanging=true]
setblock ~24 ~5 ~3 lantern[hanging=true]

fill ~3 ~7 ~3 ~26 ~7 ~26 deepslate_tiles
fill ~4 ~8 ~4 ~25 ~8 ~25 deepslate_tiles
fill ~5 ~9 ~5 ~24 ~9 ~24 deepslate_tiles
fill ~6 ~10 ~6 ~23 ~10 ~23 deepslate_tiles
fill ~7 ~11 ~7 ~22 ~11 ~22 deepslate_tiles
fill ~8 ~12 ~8 ~21 ~12 ~21 deepslate_tiles
fill ~4 ~7 ~4 ~25 ~11 ~25 air

fill ~3 ~13 ~2 ~26 ~18 ~2 black_concrete

fill ~4 ~14 ~2 ~6 ~18 ~2 sea_lantern
fill ~4 ~14 ~2 ~4 ~18 ~2 sea_lantern
fill ~4 ~14 ~2 ~6 ~14 ~2 sea_lantern
fill ~4 ~18 ~2 ~6 ~18 ~2 sea_lantern

fill ~8 ~14 ~2 ~10 ~18 ~2 sea_lantern
fill ~8 ~14 ~2 ~8 ~18 ~2 sea_lantern
fill ~10 ~14 ~2 ~10 ~18 ~2 sea_lantern
fill ~8 ~16 ~2 ~10 ~16 ~2 sea_lantern
fill ~8 ~18 ~2 ~10 ~18 ~2 sea_lantern

fill ~12 ~14 ~2 ~14 ~18 ~2 sea_lantern
fill ~12 ~14 ~2 ~14 ~14 ~2 sea_lantern
fill ~12 ~16 ~2 ~14 ~16 ~2 sea_lantern
fill ~12 ~14 ~2 ~12 ~16 ~2 sea_lantern
fill ~14 ~16 ~2 ~14 ~18 ~2 sea_lantern

fill ~16 ~14 ~2 ~18 ~18 ~2 sea_lantern
fill ~16 ~14 ~2 ~18 ~14 ~2 sea_lantern
fill ~16 ~16 ~2 ~18 ~16 ~2 sea_lantern
fill ~16 ~18 ~2 ~18 ~18 ~2 sea_lantern
fill ~16 ~14 ~2 ~16 ~16 ~2 sea_lantern
fill ~18 ~16 ~2 ~18 ~18 ~2 sea_lantern

fill ~20 ~14 ~2 ~22 ~18 ~2 sea_lantern
fill ~20 ~14 ~2 ~22 ~14 ~2 sea_lantern
fill ~20 ~16 ~2 ~22 ~16 ~2 sea_lantern
fill ~20 ~14 ~2 ~20 ~16 ~2 sea_lantern
fill ~22 ~16 ~2 ~22 ~18 ~2 sea_lantern
fill ~20 ~18 ~2 ~22 ~18 ~2 sea_lantern

fill ~24 ~14 ~2 ~26 ~18 ~2 sea_lantern
fill ~24 ~14 ~2 ~24 ~18 ~2 sea_lantern
fill ~26 ~14 ~2 ~26 ~18 ~2 sea_lantern
fill ~24 ~14 ~2 ~26 ~14 ~2 sea_lantern
fill ~24 ~18 ~2 ~26 ~18 ~2 sea_lantern

fill ~8 ~1 ~8 ~21 ~1 ~21 dark_red_carpet
fill ~10 ~1 ~16 ~19 ~1 ~21 green_carpet
fill ~6 ~1 ~10 ~7 ~1 ~20 black_concrete
fill ~22 ~1 ~10 ~23 ~1 ~20 black_concrete

fill ~11 ~1 ~10 ~18 ~1 ~11 dark_oak_slab[type=top]
fill ~11 ~1 ~13 ~18 ~1 ~14 dark_oak_slab[type=top]
fill ~11 ~1 ~16 ~18 ~1 ~17 dark_oak_slab[type=top]

setblock ~13 ~2 ~12 lantern
setblock ~16 ~2 ~12 lantern
setblock ~13 ~2 ~15 lantern
setblock ~16 ~2 ~15 lantern

say Casino: construido.
